Sample of generation of error for Mock.
=======================================

.. Python < 3 compatibility
    >>> import ludibrio.specification.compat

::

    >>> from ludibrio import Mock

    >>> with Mock() as teste:
    ...     teste.called() << 1
    ...     teste.notcalled() << 2
    >>> gotnumber = teste.called()
    >>> teste.validate()
    ... 
    Traceback (most recent call last):
    ...
    ludibrio.mock.MockExpectationError: Call waiting: notcalled


::

    >>> with Mock() as greetings:
    ...     greetings.excuse_me() >> 'Com licença'
    ...     greetings.see_you_soon >> 'Até logo'
    >>> print greetings.excuse_me()
    Com licença
    >>> print greetings.hello('Gustavo Rezende')
    Traceback (most recent call last):
    ...
    ludibrio.mock.MockExpectationError: Mock Object received unexpected call:hello


::

    >>> with Mock() as greetings:
    ...     greetings.excuse_me(name='gustavo') >> 'Com licença'
    >>> greetings.excuse_me(name='Diego Manhaes')
    Traceback (most recent call last):
    ...
    ludibrio.mock.MockExpectationError: Mock Object received unexpected call:excuse_me(name='Diego Manhaes')
